Running SLURM prolog script on pink51
===============================================================================
Job started on Mon Aug  6 21:39:10 BST 2018
Job ID          : 124874
Job name        : saliency-batch
WorkDir         : /mainfs/lyceum/grm1g17/lasagne4bio/test_saliency
Partition       : lyceum
Num hosts       : 1
Num cores       : 14
Num of tasks    : 14
Hosts allocated : pink51
Job Output Follows ...
===============================================================================
/lyceum/grm1g17/.conda/envs/localenv/lib/python3.5/importlib/_bootstrap.py:222: RuntimeWarning: numpy.dtype size changed, may indicate binary incompatibility. Expected 96, got 88
  return f(*args, **kwds)
Using cuDNN version 7005 on context None
Mapped name None to device cuda: GeForce GTX 1080 Ti (0000:82:00.0)
/lyceum/grm1g17/.conda/envs/localenv/lib/python3.5/importlib/_bootstrap.py:222: RuntimeWarning: numpy.dtype size changed, may indicate binary incompatibility. Expected 96, got 88
  return f(*args, **kwds)
Using Theano backend.
Traceback (most recent call last):
  File "saliency.py", line 173, in <module>
    main_saliencies_jurtz()
  File "saliency.py", line 165, in main_saliencies_jurtz
    X_batch, mask_batch = dater.get_batch_from_seq(first_seq)
  File "/mainfs/lyceum/grm1g17/lasagne4bio/test_saliency/utils.py", line 61, in get_batch_from_seq
    self.update_data(sequence)
  File "/mainfs/lyceum/grm1g17/lasagne4bio/test_saliency/utils.py", line 90, in update_data
    elif sequence >= 5504 and self.subset is not "test":
AttributeError: 'Jurtz_Data' object has no attribute 'subset'
/lyceum/grm1g17/.conda/envs/localenv/lib/python3.5/importlib/_bootstrap.py:222: RuntimeWarning: numpy.dtype size changed, may indicate binary incompatibility. Expected 96, got 88
  return f(*args, **kwds)
INFO (theano.gof.compilelock): Waiting for existing lock by process '49721' (I am process '49288')
INFO (theano.gof.compilelock): To manually release the lock, delete /mainfs/lyceum/grm1g17/.theano/compiledir_Linux-3.10-el7.x86_64-x86_64-with-redhat-7.4-Maipo-x86_64-3.5.5-64/lock_dir
INFO (theano.gof.compilelock): Waiting for existing lock by process '15104' (I am process '49288')
INFO (theano.gof.compilelock): To manually release the lock, delete /mainfs/lyceum/grm1g17/.theano/compiledir_Linux-3.10-el7.x86_64-x86_64-with-redhat-7.4-Maipo-x86_64-3.5.5-64/lock_dir
Using cuDNN version 7005 on context None
Mapped name None to device cuda: GeForce GTX 1080 Ti (0000:82:00.0)
/lyceum/grm1g17/.conda/envs/localenv/lib/python3.5/importlib/_bootstrap.py:222: RuntimeWarning: numpy.dtype size changed, may indicate binary incompatibility. Expected 96, got 88
  return f(*args, **kwds)
Using Theano backend.
Traceback (most recent call last):
  File "saliency.py", line 173, in <module>
    main_saliencies_jurtz()
  File "saliency.py", line 165, in main_saliencies_jurtz
    X_batch, mask_batch = dater.get_batch_from_seq(first_seq)
  File "/mainfs/lyceum/grm1g17/lasagne4bio/test_saliency/utils.py", line 61, in get_batch_from_seq
    self.update_data(sequence)
  File "/mainfs/lyceum/grm1g17/lasagne4bio/test_saliency/utils.py", line 90, in update_data
    elif sequence >= 5504 and self.subset is not "test":
AttributeError: 'Jurtz_Data' object has no attribute 'subset'
/lyceum/grm1g17/.conda/envs/localenv/lib/python3.5/importlib/_bootstrap.py:222: RuntimeWarning: numpy.dtype size changed, may indicate binary incompatibility. Expected 96, got 88
  return f(*args, **kwds)
Using cuDNN version 7005 on context None
Mapped name None to device cuda: GeForce GTX 1080 Ti (0000:82:00.0)
/lyceum/grm1g17/.conda/envs/localenv/lib/python3.5/importlib/_bootstrap.py:222: RuntimeWarning: numpy.dtype size changed, may indicate binary incompatibility. Expected 96, got 88
  return f(*args, **kwds)
Using Theano backend.
Traceback (most recent call last):
  File "saliency.py", line 173, in <module>
    main_saliencies_jurtz()
  File "saliency.py", line 165, in main_saliencies_jurtz
    X_batch, mask_batch = dater.get_batch_from_seq(first_seq)
  File "/mainfs/lyceum/grm1g17/lasagne4bio/test_saliency/utils.py", line 61, in get_batch_from_seq
    self.update_data(sequence)
  File "/mainfs/lyceum/grm1g17/lasagne4bio/test_saliency/utils.py", line 90, in update_data
    elif sequence >= 5504 and self.subset is not "test":
AttributeError: 'Jurtz_Data' object has no attribute 'subset'
/lyceum/grm1g17/.conda/envs/localenv/lib/python3.5/importlib/_bootstrap.py:222: RuntimeWarning: numpy.dtype size changed, may indicate binary incompatibility. Expected 96, got 88
  return f(*args, **kwds)
Using cuDNN version 7005 on context None
Mapped name None to device cuda: GeForce GTX 1080 Ti (0000:82:00.0)
/lyceum/grm1g17/.conda/envs/localenv/lib/python3.5/importlib/_bootstrap.py:222: RuntimeWarning: numpy.dtype size changed, may indicate binary incompatibility. Expected 96, got 88
  return f(*args, **kwds)
Using Theano backend.
Traceback (most recent call last):
  File "saliency.py", line 173, in <module>
    main_saliencies_jurtz()
  File "saliency.py", line 165, in main_saliencies_jurtz
    X_batch, mask_batch = dater.get_batch_from_seq(first_seq)
  File "/mainfs/lyceum/grm1g17/lasagne4bio/test_saliency/utils.py", line 61, in get_batch_from_seq
    self.update_data(sequence)
  File "/mainfs/lyceum/grm1g17/lasagne4bio/test_saliency/utils.py", line 90, in update_data
    elif sequence >= 5504 and self.subset is not "test":
AttributeError: 'Jurtz_Data' object has no attribute 'subset'
/lyceum/grm1g17/.conda/envs/localenv/lib/python3.5/importlib/_bootstrap.py:222: RuntimeWarning: numpy.dtype size changed, may indicate binary incompatibility. Expected 96, got 88
  return f(*args, **kwds)
INFO (theano.gof.compilelock): Waiting for existing lock by process '16023' (I am process '2717')
INFO (theano.gof.compilelock): To manually release the lock, delete /mainfs/lyceum/grm1g17/.theano/compiledir_Linux-3.10-el7.x86_64-x86_64-with-redhat-7.4-Maipo-x86_64-3.5.5-64/lock_dir
INFO (theano.gof.compilelock): Waiting for existing lock by unknown process (I am process '2717')
INFO (theano.gof.compilelock): To manually release the lock, delete /mainfs/lyceum/grm1g17/.theano/compiledir_Linux-3.10-el7.x86_64-x86_64-with-redhat-7.4-Maipo-x86_64-3.5.5-64/lock_dir
INFO (theano.gof.compilelock): Refreshing lock /mainfs/lyceum/grm1g17/.theano/compiledir_Linux-3.10-el7.x86_64-x86_64-with-redhat-7.4-Maipo-x86_64-3.5.5-64/lock_dir/lock
ERROR (theano.gpuarray): Could not initialize pygpu, support disabled
Traceback (most recent call last):
  File "/lyceum/grm1g17/.conda/envs/localenv/lib/python3.5/site-packages/theano/gpuarray/__init__.py", line 227, in <module>
    use(config.device)
  File "/lyceum/grm1g17/.conda/envs/localenv/lib/python3.5/site-packages/theano/gpuarray/__init__.py", line 214, in use
    init_dev(device, preallocate=preallocate)
  File "/lyceum/grm1g17/.conda/envs/localenv/lib/python3.5/site-packages/theano/gpuarray/__init__.py", line 99, in init_dev
    **args)
  File "pygpu/gpuarray.pyx", line 658, in pygpu.gpuarray.init
  File "pygpu/gpuarray.pyx", line 587, in pygpu.gpuarray.pygpu_init
pygpu.gpuarray.GpuArrayException: b'cuInit: CUDA_ERROR_NOT_INITIALIZED: initialization error'
/lyceum/grm1g17/.conda/envs/localenv/lib/python3.5/importlib/_bootstrap.py:222: RuntimeWarning: numpy.dtype size changed, may indicate binary incompatibility. Expected 96, got 88
  return f(*args, **kwds)
Using Theano backend.
Traceback (most recent call last):
  File "saliency.py", line 173, in <module>
    main_saliencies_jurtz()
  File "saliency.py", line 165, in main_saliencies_jurtz
    X_batch, mask_batch = dater.get_batch_from_seq(first_seq)
  File "/mainfs/lyceum/grm1g17/lasagne4bio/test_saliency/utils.py", line 61, in get_batch_from_seq
    self.update_data(sequence)
  File "/mainfs/lyceum/grm1g17/lasagne4bio/test_saliency/utils.py", line 90, in update_data
    elif sequence >= 5504 and self.subset is not "test":
AttributeError: 'Jurtz_Data' object has no attribute 'subset'
/lyceum/grm1g17/.conda/envs/localenv/lib/python3.5/importlib/_bootstrap.py:222: RuntimeWarning: numpy.dtype size changed, may indicate binary incompatibility. Expected 96, got 88
  return f(*args, **kwds)
Using cuDNN version 7005 on context None
Mapped name None to device cuda: GeForce GTX 1080 Ti (0000:82:00.0)
/lyceum/grm1g17/.conda/envs/localenv/lib/python3.5/importlib/_bootstrap.py:222: RuntimeWarning: numpy.dtype size changed, may indicate binary incompatibility. Expected 96, got 88
  return f(*args, **kwds)
Using Theano backend.
Traceback (most recent call last):
  File "saliency.py", line 173, in <module>
    main_saliencies_jurtz()
  File "saliency.py", line 165, in main_saliencies_jurtz
    X_batch, mask_batch = dater.get_batch_from_seq(first_seq)
  File "/mainfs/lyceum/grm1g17/lasagne4bio/test_saliency/utils.py", line 61, in get_batch_from_seq
    self.update_data(sequence)
  File "/mainfs/lyceum/grm1g17/lasagne4bio/test_saliency/utils.py", line 90, in update_data
    elif sequence >= 5504 and self.subset is not "test":
AttributeError: 'Jurtz_Data' object has no attribute 'subset'
/lyceum/grm1g17/.conda/envs/localenv/lib/python3.5/importlib/_bootstrap.py:222: RuntimeWarning: numpy.dtype size changed, may indicate binary incompatibility. Expected 96, got 88
  return f(*args, **kwds)
Using cuDNN version 7005 on context None
Mapped name None to device cuda: GeForce GTX 1080 Ti (0000:82:00.0)
/lyceum/grm1g17/.conda/envs/localenv/lib/python3.5/importlib/_bootstrap.py:222: RuntimeWarning: numpy.dtype size changed, may indicate binary incompatibility. Expected 96, got 88
  return f(*args, **kwds)
Using Theano backend.
Traceback (most recent call last):
  File "saliency.py", line 173, in <module>
    main_saliencies_jurtz()
  File "saliency.py", line 165, in main_saliencies_jurtz
    X_batch, mask_batch = dater.get_batch_from_seq(first_seq)
  File "/mainfs/lyceum/grm1g17/lasagne4bio/test_saliency/utils.py", line 61, in get_batch_from_seq
    self.update_data(sequence)
  File "/mainfs/lyceum/grm1g17/lasagne4bio/test_saliency/utils.py", line 90, in update_data
    elif sequence >= 5504 and self.subset is not "test":
AttributeError: 'Jurtz_Data' object has no attribute 'subset'
/lyceum/grm1g17/.conda/envs/localenv/lib/python3.5/importlib/_bootstrap.py:222: RuntimeWarning: numpy.dtype size changed, may indicate binary incompatibility. Expected 96, got 88
  return f(*args, **kwds)
Using cuDNN version 7005 on context None
Mapped name None to device cuda: GeForce GTX 1080 Ti (0000:82:00.0)
/lyceum/grm1g17/.conda/envs/localenv/lib/python3.5/importlib/_bootstrap.py:222: RuntimeWarning: numpy.dtype size changed, may indicate binary incompatibility. Expected 96, got 88
  return f(*args, **kwds)
Using Theano backend.
Traceback (most recent call last):
  File "saliency.py", line 173, in <module>
    main_saliencies_jurtz()
  File "saliency.py", line 165, in main_saliencies_jurtz
    X_batch, mask_batch = dater.get_batch_from_seq(first_seq)
  File "/mainfs/lyceum/grm1g17/lasagne4bio/test_saliency/utils.py", line 61, in get_batch_from_seq
    self.update_data(sequence)
  File "/mainfs/lyceum/grm1g17/lasagne4bio/test_saliency/utils.py", line 90, in update_data
    elif sequence >= 5504 and self.subset is not "test":
AttributeError: 'Jurtz_Data' object has no attribute 'subset'
==============================================================================
Running epilogue script on pink51.

Submit time  : 2018-08-06T18:35:22
Start time   : 2018-08-06T21:39:10
End time     : 2018-08-06T22:02:39
Elapsed time : 00:23:29 (Timelimit=04:40:00)

Job ID: 124874
Array Job ID: 124818_91
Cluster: i5
User/Group: grm1g17/fp
State: FAILED (exit code 1)
Nodes: 1
Cores per node: 14
CPU Utilized: 00:02:27
**** Please note that the CPU efficency of your job is less than 50% ****
**** Ask the HPC team for advice -- if you need it
**** CPU Efficiency: 0.75% of 05:28:46 core-walltime

Memory Utilized: 1.48 GB

