Running SLURM prolog script on pink58
===============================================================================
Job started on Tue Aug  7 00:27:26 BST 2018
Job ID          : 124923
Job name        : saliency-batch
WorkDir         : /mainfs/lyceum/grm1g17/lasagne4bio/test_saliency
Partition       : lyceum
Num hosts       : 1
Num cores       : 14
Num of tasks    : 14
Hosts allocated : pink58
Job Output Follows ...
===============================================================================
/bin/sh: ./download_test.sh: No such file or directory
/lyceum/grm1g17/.conda/envs/localenv/lib/python3.5/importlib/_bootstrap.py:222: RuntimeWarning: numpy.dtype size changed, may indicate binary incompatibility. Expected 96, got 88
  return f(*args, **kwds)
Using cuDNN version 7005 on context None
Mapped name None to device cuda: GeForce GTX 1080 Ti (0000:82:00.0)
/lyceum/grm1g17/.conda/envs/localenv/lib/python3.5/importlib/_bootstrap.py:222: RuntimeWarning: numpy.dtype size changed, may indicate binary incompatibility. Expected 96, got 88
  return f(*args, **kwds)
Using Theano backend.
Loading test data ...
Traceback (most recent call last):
  File "saliency.py", line 173, in <module>
    main_saliencies_jurtz()
  File "saliency.py", line 163, in main_saliencies_jurtz
    dater = Jurtz_Data()
  File "/mainfs/lyceum/grm1g17/lasagne4bio/test_saliency/utils.py", line 54, in __init__
    self.get_test = get_test()
  File "/mainfs/lyceum/grm1g17/lasagne4bio/test_saliency/data.py", line 77, in get_test
    X_test_in = utils.load_gz(path)
  File "/mainfs/lyceum/grm1g17/lasagne4bio/test_saliency/utils.py", line 41, in load_gz
    f = gzip.open(path, 'rb')
  File "/lyceum/grm1g17/.conda/envs/localenv/lib/python3.5/gzip.py", line 53, in open
    binary_file = GzipFile(filename, gz_mode, compresslevel)
  File "/lyceum/grm1g17/.conda/envs/localenv/lib/python3.5/gzip.py", line 163, in __init__
    fileobj = self.myfileobj = builtins.open(filename, mode or 'rb')
FileNotFoundError: [Errno 2] No such file or directory: 'data/cb513+profile_split1.npy.gz'
/bin/sh: ./download_test.sh: No such file or directory
/lyceum/grm1g17/.conda/envs/localenv/lib/python3.5/importlib/_bootstrap.py:222: RuntimeWarning: numpy.dtype size changed, may indicate binary incompatibility. Expected 96, got 88
  return f(*args, **kwds)
Using cuDNN version 7005 on context None
Mapped name None to device cuda: GeForce GTX 1080 Ti (0000:82:00.0)
/lyceum/grm1g17/.conda/envs/localenv/lib/python3.5/importlib/_bootstrap.py:222: RuntimeWarning: numpy.dtype size changed, may indicate binary incompatibility. Expected 96, got 88
  return f(*args, **kwds)
Using Theano backend.
Loading test data ...
Traceback (most recent call last):
  File "saliency.py", line 173, in <module>
    main_saliencies_jurtz()
  File "saliency.py", line 163, in main_saliencies_jurtz
    dater = Jurtz_Data()
  File "/mainfs/lyceum/grm1g17/lasagne4bio/test_saliency/utils.py", line 54, in __init__
    self.get_test = get_test()
  File "/mainfs/lyceum/grm1g17/lasagne4bio/test_saliency/data.py", line 77, in get_test
    X_test_in = utils.load_gz(path)
  File "/mainfs/lyceum/grm1g17/lasagne4bio/test_saliency/utils.py", line 41, in load_gz
    f = gzip.open(path, 'rb')
  File "/lyceum/grm1g17/.conda/envs/localenv/lib/python3.5/gzip.py", line 53, in open
    binary_file = GzipFile(filename, gz_mode, compresslevel)
  File "/lyceum/grm1g17/.conda/envs/localenv/lib/python3.5/gzip.py", line 163, in __init__
    fileobj = self.myfileobj = builtins.open(filename, mode or 'rb')
FileNotFoundError: [Errno 2] No such file or directory: 'data/cb513+profile_split1.npy.gz'
/bin/sh: ./download_test.sh: No such file or directory
/lyceum/grm1g17/.conda/envs/localenv/lib/python3.5/importlib/_bootstrap.py:222: RuntimeWarning: numpy.dtype size changed, may indicate binary incompatibility. Expected 96, got 88
  return f(*args, **kwds)
Using cuDNN version 7005 on context None
Mapped name None to device cuda: GeForce GTX 1080 Ti (0000:82:00.0)
/lyceum/grm1g17/.conda/envs/localenv/lib/python3.5/importlib/_bootstrap.py:222: RuntimeWarning: numpy.dtype size changed, may indicate binary incompatibility. Expected 96, got 88
  return f(*args, **kwds)
Using Theano backend.
Loading test data ...
Traceback (most recent call last):
  File "saliency.py", line 173, in <module>
    main_saliencies_jurtz()
  File "saliency.py", line 163, in main_saliencies_jurtz
    dater = Jurtz_Data()
  File "/mainfs/lyceum/grm1g17/lasagne4bio/test_saliency/utils.py", line 54, in __init__
    self.get_test = get_test()
  File "/mainfs/lyceum/grm1g17/lasagne4bio/test_saliency/data.py", line 77, in get_test
    X_test_in = utils.load_gz(path)
  File "/mainfs/lyceum/grm1g17/lasagne4bio/test_saliency/utils.py", line 41, in load_gz
    f = gzip.open(path, 'rb')
  File "/lyceum/grm1g17/.conda/envs/localenv/lib/python3.5/gzip.py", line 53, in open
    binary_file = GzipFile(filename, gz_mode, compresslevel)
  File "/lyceum/grm1g17/.conda/envs/localenv/lib/python3.5/gzip.py", line 163, in __init__
    fileobj = self.myfileobj = builtins.open(filename, mode or 'rb')
FileNotFoundError: [Errno 2] No such file or directory: 'data/cb513+profile_split1.npy.gz'
/bin/sh: ./download_test.sh: No such file or directory
/lyceum/grm1g17/.conda/envs/localenv/lib/python3.5/importlib/_bootstrap.py:222: RuntimeWarning: numpy.dtype size changed, may indicate binary incompatibility. Expected 96, got 88
  return f(*args, **kwds)
Using cuDNN version 7005 on context None
Mapped name None to device cuda: GeForce GTX 1080 Ti (0000:82:00.0)
/lyceum/grm1g17/.conda/envs/localenv/lib/python3.5/importlib/_bootstrap.py:222: RuntimeWarning: numpy.dtype size changed, may indicate binary incompatibility. Expected 96, got 88
  return f(*args, **kwds)
Using Theano backend.
Loading test data ...
Traceback (most recent call last):
  File "saliency.py", line 173, in <module>
    main_saliencies_jurtz()
  File "saliency.py", line 163, in main_saliencies_jurtz
    dater = Jurtz_Data()
  File "/mainfs/lyceum/grm1g17/lasagne4bio/test_saliency/utils.py", line 54, in __init__
    self.get_test = get_test()
  File "/mainfs/lyceum/grm1g17/lasagne4bio/test_saliency/data.py", line 77, in get_test
    X_test_in = utils.load_gz(path)
  File "/mainfs/lyceum/grm1g17/lasagne4bio/test_saliency/utils.py", line 41, in load_gz
    f = gzip.open(path, 'rb')
  File "/lyceum/grm1g17/.conda/envs/localenv/lib/python3.5/gzip.py", line 53, in open
    binary_file = GzipFile(filename, gz_mode, compresslevel)
  File "/lyceum/grm1g17/.conda/envs/localenv/lib/python3.5/gzip.py", line 163, in __init__
    fileobj = self.myfileobj = builtins.open(filename, mode or 'rb')
FileNotFoundError: [Errno 2] No such file or directory: 'data/cb513+profile_split1.npy.gz'
/bin/sh: ./download_test.sh: No such file or directory
/lyceum/grm1g17/.conda/envs/localenv/lib/python3.5/importlib/_bootstrap.py:222: RuntimeWarning: numpy.dtype size changed, may indicate binary incompatibility. Expected 96, got 88
  return f(*args, **kwds)
Using cuDNN version 7005 on context None
Mapped name None to device cuda: GeForce GTX 1080 Ti (0000:82:00.0)
/lyceum/grm1g17/.conda/envs/localenv/lib/python3.5/importlib/_bootstrap.py:222: RuntimeWarning: numpy.dtype size changed, may indicate binary incompatibility. Expected 96, got 88
  return f(*args, **kwds)
Using Theano backend.
Loading test data ...
Traceback (most recent call last):
  File "saliency.py", line 173, in <module>
    main_saliencies_jurtz()
  File "saliency.py", line 163, in main_saliencies_jurtz
    dater = Jurtz_Data()
  File "/mainfs/lyceum/grm1g17/lasagne4bio/test_saliency/utils.py", line 54, in __init__
    self.get_test = get_test()
  File "/mainfs/lyceum/grm1g17/lasagne4bio/test_saliency/data.py", line 77, in get_test
    X_test_in = utils.load_gz(path)
  File "/mainfs/lyceum/grm1g17/lasagne4bio/test_saliency/utils.py", line 41, in load_gz
    f = gzip.open(path, 'rb')
  File "/lyceum/grm1g17/.conda/envs/localenv/lib/python3.5/gzip.py", line 53, in open
    binary_file = GzipFile(filename, gz_mode, compresslevel)
  File "/lyceum/grm1g17/.conda/envs/localenv/lib/python3.5/gzip.py", line 163, in __init__
    fileobj = self.myfileobj = builtins.open(filename, mode or 'rb')
FileNotFoundError: [Errno 2] No such file or directory: 'data/cb513+profile_split1.npy.gz'
/bin/sh: ./download_test.sh: No such file or directory
/lyceum/grm1g17/.conda/envs/localenv/lib/python3.5/importlib/_bootstrap.py:222: RuntimeWarning: numpy.dtype size changed, may indicate binary incompatibility. Expected 96, got 88
  return f(*args, **kwds)
Using cuDNN version 7005 on context None
Mapped name None to device cuda: GeForce GTX 1080 Ti (0000:82:00.0)
/lyceum/grm1g17/.conda/envs/localenv/lib/python3.5/importlib/_bootstrap.py:222: RuntimeWarning: numpy.dtype size changed, may indicate binary incompatibility. Expected 96, got 88
  return f(*args, **kwds)
Using Theano backend.
Loading test data ...
Traceback (most recent call last):
  File "saliency.py", line 173, in <module>
    main_saliencies_jurtz()
  File "saliency.py", line 163, in main_saliencies_jurtz
    dater = Jurtz_Data()
  File "/mainfs/lyceum/grm1g17/lasagne4bio/test_saliency/utils.py", line 54, in __init__
    self.get_test = get_test()
  File "/mainfs/lyceum/grm1g17/lasagne4bio/test_saliency/data.py", line 77, in get_test
    X_test_in = utils.load_gz(path)
  File "/mainfs/lyceum/grm1g17/lasagne4bio/test_saliency/utils.py", line 41, in load_gz
    f = gzip.open(path, 'rb')
  File "/lyceum/grm1g17/.conda/envs/localenv/lib/python3.5/gzip.py", line 53, in open
    binary_file = GzipFile(filename, gz_mode, compresslevel)
  File "/lyceum/grm1g17/.conda/envs/localenv/lib/python3.5/gzip.py", line 163, in __init__
    fileobj = self.myfileobj = builtins.open(filename, mode or 'rb')
FileNotFoundError: [Errno 2] No such file or directory: 'data/cb513+profile_split1.npy.gz'
/bin/sh: ./download_test.sh: No such file or directory
/lyceum/grm1g17/.conda/envs/localenv/lib/python3.5/importlib/_bootstrap.py:222: RuntimeWarning: numpy.dtype size changed, may indicate binary incompatibility. Expected 96, got 88
  return f(*args, **kwds)
Using cuDNN version 7005 on context None
Mapped name None to device cuda: GeForce GTX 1080 Ti (0000:82:00.0)
/lyceum/grm1g17/.conda/envs/localenv/lib/python3.5/importlib/_bootstrap.py:222: RuntimeWarning: numpy.dtype size changed, may indicate binary incompatibility. Expected 96, got 88
  return f(*args, **kwds)
Using Theano backend.
Loading test data ...
Traceback (most recent call last):
  File "saliency.py", line 173, in <module>
    main_saliencies_jurtz()
  File "saliency.py", line 163, in main_saliencies_jurtz
    dater = Jurtz_Data()
  File "/mainfs/lyceum/grm1g17/lasagne4bio/test_saliency/utils.py", line 54, in __init__
    self.get_test = get_test()
  File "/mainfs/lyceum/grm1g17/lasagne4bio/test_saliency/data.py", line 77, in get_test
    X_test_in = utils.load_gz(path)
  File "/mainfs/lyceum/grm1g17/lasagne4bio/test_saliency/utils.py", line 41, in load_gz
    f = gzip.open(path, 'rb')
  File "/lyceum/grm1g17/.conda/envs/localenv/lib/python3.5/gzip.py", line 53, in open
    binary_file = GzipFile(filename, gz_mode, compresslevel)
  File "/lyceum/grm1g17/.conda/envs/localenv/lib/python3.5/gzip.py", line 163, in __init__
    fileobj = self.myfileobj = builtins.open(filename, mode or 'rb')
FileNotFoundError: [Errno 2] No such file or directory: 'data/cb513+profile_split1.npy.gz'
/bin/sh: ./download_test.sh: No such file or directory
/lyceum/grm1g17/.conda/envs/localenv/lib/python3.5/importlib/_bootstrap.py:222: RuntimeWarning: numpy.dtype size changed, may indicate binary incompatibility. Expected 96, got 88
  return f(*args, **kwds)
Using cuDNN version 7005 on context None
Mapped name None to device cuda: GeForce GTX 1080 Ti (0000:82:00.0)
/lyceum/grm1g17/.conda/envs/localenv/lib/python3.5/importlib/_bootstrap.py:222: RuntimeWarning: numpy.dtype size changed, may indicate binary incompatibility. Expected 96, got 88
  return f(*args, **kwds)
Using Theano backend.
Loading test data ...
Traceback (most recent call last):
  File "saliency.py", line 173, in <module>
    main_saliencies_jurtz()
  File "saliency.py", line 163, in main_saliencies_jurtz
    dater = Jurtz_Data()
  File "/mainfs/lyceum/grm1g17/lasagne4bio/test_saliency/utils.py", line 54, in __init__
    self.get_test = get_test()
  File "/mainfs/lyceum/grm1g17/lasagne4bio/test_saliency/data.py", line 77, in get_test
    X_test_in = utils.load_gz(path)
  File "/mainfs/lyceum/grm1g17/lasagne4bio/test_saliency/utils.py", line 41, in load_gz
    f = gzip.open(path, 'rb')
  File "/lyceum/grm1g17/.conda/envs/localenv/lib/python3.5/gzip.py", line 53, in open
    binary_file = GzipFile(filename, gz_mode, compresslevel)
  File "/lyceum/grm1g17/.conda/envs/localenv/lib/python3.5/gzip.py", line 163, in __init__
    fileobj = self.myfileobj = builtins.open(filename, mode or 'rb')
FileNotFoundError: [Errno 2] No such file or directory: 'data/cb513+profile_split1.npy.gz'
==============================================================================
Running epilogue script on pink58.

Submit time  : 2018-08-06T23:33:16
Start time   : 2018-08-07T00:27:26
End time     : 2018-08-07T00:42:49
Elapsed time : 00:15:23 (Timelimit=04:40:00)

Job ID: 124923
Array Job ID: 124913_83
Cluster: i5
User/Group: grm1g17/fp
State: FAILED (exit code 1)
Nodes: 1
Cores per node: 14
CPU Utilized: 00:02:17
**** Please note that the CPU efficency of your job is less than 50% ****
**** Ask the HPC team for advice -- if you need it
**** CPU Efficiency: 1.06% of 03:35:22 core-walltime

Memory Utilized: 1.48 GB

