Running SLURM prolog script on pink54
===============================================================================
Job started on Mon Aug  6 17:50:30 BST 2018
Job ID          : 124807
Job name        : saliency-batch
WorkDir         : /mainfs/lyceum/grm1g17/lasagne4bio/test_saliency
Partition       : lyceum
Num hosts       : 1
Num cores       : 14
Num of tasks    : 14
Hosts allocated : pink54
Job Output Follows ...
===============================================================================
/lyceum/grm1g17/.conda/envs/localenv/lib/python3.5/importlib/_bootstrap.py:222: RuntimeWarning: numpy.dtype size changed, may indicate binary incompatibility. Expected 96, got 88
  return f(*args, **kwds)
INFO (theano.gof.compilelock): Waiting for existing lock by process '57322' (I am process '54725')
INFO (theano.gof.compilelock): To manually release the lock, delete /mainfs/lyceum/grm1g17/.theano/compiledir_Linux-3.10-el7.x86_64-x86_64-with-redhat-7.4-Maipo-x86_64-3.5.5-64/lock_dir
INFO (theano.gof.compilelock): Waiting for existing lock by process '57322' (I am process '54725')
INFO (theano.gof.compilelock): To manually release the lock, delete /mainfs/lyceum/grm1g17/.theano/compiledir_Linux-3.10-el7.x86_64-x86_64-with-redhat-7.4-Maipo-x86_64-3.5.5-64/lock_dir
Using cuDNN version 7005 on context None
Mapped name None to device cuda: GeForce GTX 1080 Ti (0000:03:00.0)
/lyceum/grm1g17/.conda/envs/localenv/lib/python3.5/importlib/_bootstrap.py:222: RuntimeWarning: numpy.dtype size changed, may indicate binary incompatibility. Expected 96, got 88
  return f(*args, **kwds)
Using Theano backend.
Train path is downloaded ...
Loading train data ...
Loading splits ...
Traceback (most recent call last):
  File "saliency.py", line 312, in <module>
    main_saliencies_jurtz()
  File "saliency.py", line 256, in main_saliencies_jurtz
    compute_tensor_jurtz(X[idx], mask[idx], args.batch, args.label)
IndexError: index 256 is out of bounds for axis 0 with size 256
/lyceum/grm1g17/.conda/envs/localenv/lib/python3.5/importlib/_bootstrap.py:222: RuntimeWarning: numpy.dtype size changed, may indicate binary incompatibility. Expected 96, got 88
  return f(*args, **kwds)
Using cuDNN version 7005 on context None
Mapped name None to device cuda: GeForce GTX 1080 Ti (0000:03:00.0)
/lyceum/grm1g17/.conda/envs/localenv/lib/python3.5/importlib/_bootstrap.py:222: RuntimeWarning: numpy.dtype size changed, may indicate binary incompatibility. Expected 96, got 88
  return f(*args, **kwds)
Using Theano backend.
Train path is downloaded ...
Loading train data ...
Loading splits ...
Traceback (most recent call last):
  File "saliency.py", line 312, in <module>
    main_saliencies_jurtz()
  File "saliency.py", line 256, in main_saliencies_jurtz
    compute_tensor_jurtz(X[idx], mask[idx], args.batch, args.label)
IndexError: index 256 is out of bounds for axis 0 with size 256
/lyceum/grm1g17/.conda/envs/localenv/lib/python3.5/importlib/_bootstrap.py:222: RuntimeWarning: numpy.dtype size changed, may indicate binary incompatibility. Expected 96, got 88
  return f(*args, **kwds)
Using cuDNN version 7005 on context None
Mapped name None to device cuda: GeForce GTX 1080 Ti (0000:03:00.0)
/lyceum/grm1g17/.conda/envs/localenv/lib/python3.5/importlib/_bootstrap.py:222: RuntimeWarning: numpy.dtype size changed, may indicate binary incompatibility. Expected 96, got 88
  return f(*args, **kwds)
Using Theano backend.
Train path is downloaded ...
Loading train data ...
Loading splits ...
Traceback (most recent call last):
  File "saliency.py", line 312, in <module>
    main_saliencies_jurtz()
  File "saliency.py", line 256, in main_saliencies_jurtz
    compute_tensor_jurtz(X[idx], mask[idx], args.batch, args.label)
IndexError: index 256 is out of bounds for axis 0 with size 256
/lyceum/grm1g17/.conda/envs/localenv/lib/python3.5/importlib/_bootstrap.py:222: RuntimeWarning: numpy.dtype size changed, may indicate binary incompatibility. Expected 96, got 88
  return f(*args, **kwds)
INFO (theano.gof.compilelock): Waiting for existing lock by process '4101' (I am process '56041')
INFO (theano.gof.compilelock): To manually release the lock, delete /mainfs/lyceum/grm1g17/.theano/compiledir_Linux-3.10-el7.x86_64-x86_64-with-redhat-7.4-Maipo-x86_64-3.5.5-64/lock_dir
INFO (theano.gof.compilelock): Waiting for existing lock by process '4101' (I am process '56041')
INFO (theano.gof.compilelock): To manually release the lock, delete /mainfs/lyceum/grm1g17/.theano/compiledir_Linux-3.10-el7.x86_64-x86_64-with-redhat-7.4-Maipo-x86_64-3.5.5-64/lock_dir
INFO (theano.gof.compilelock): Waiting for existing lock by process '4101' (I am process '56041')
INFO (theano.gof.compilelock): To manually release the lock, delete /mainfs/lyceum/grm1g17/.theano/compiledir_Linux-3.10-el7.x86_64-x86_64-with-redhat-7.4-Maipo-x86_64-3.5.5-64/lock_dir
INFO (theano.gof.compilelock): Waiting for existing lock by process '4101' (I am process '56041')
INFO (theano.gof.compilelock): To manually release the lock, delete /mainfs/lyceum/grm1g17/.theano/compiledir_Linux-3.10-el7.x86_64-x86_64-with-redhat-7.4-Maipo-x86_64-3.5.5-64/lock_dir
INFO (theano.gof.compilelock): Waiting for existing lock by process '4101' (I am process '56041')
INFO (theano.gof.compilelock): To manually release the lock, delete /mainfs/lyceum/grm1g17/.theano/compiledir_Linux-3.10-el7.x86_64-x86_64-with-redhat-7.4-Maipo-x86_64-3.5.5-64/lock_dir
INFO (theano.gof.compilelock): Waiting for existing lock by process '4101' (I am process '56041')
INFO (theano.gof.compilelock): To manually release the lock, delete /mainfs/lyceum/grm1g17/.theano/compiledir_Linux-3.10-el7.x86_64-x86_64-with-redhat-7.4-Maipo-x86_64-3.5.5-64/lock_dir
INFO (theano.gof.compilelock): Waiting for existing lock by process '4101' (I am process '56041')
INFO (theano.gof.compilelock): To manually release the lock, delete /mainfs/lyceum/grm1g17/.theano/compiledir_Linux-3.10-el7.x86_64-x86_64-with-redhat-7.4-Maipo-x86_64-3.5.5-64/lock_dir
INFO (theano.gof.compilelock): Waiting for existing lock by process '4101' (I am process '56041')
INFO (theano.gof.compilelock): To manually release the lock, delete /mainfs/lyceum/grm1g17/.theano/compiledir_Linux-3.10-el7.x86_64-x86_64-with-redhat-7.4-Maipo-x86_64-3.5.5-64/lock_dir
INFO (theano.gof.compilelock): Waiting for existing lock by process '4101' (I am process '56041')
INFO (theano.gof.compilelock): To manually release the lock, delete /mainfs/lyceum/grm1g17/.theano/compiledir_Linux-3.10-el7.x86_64-x86_64-with-redhat-7.4-Maipo-x86_64-3.5.5-64/lock_dir
INFO (theano.gof.compilelock): Waiting for existing lock by process '4101' (I am process '56041')
INFO (theano.gof.compilelock): To manually release the lock, delete /mainfs/lyceum/grm1g17/.theano/compiledir_Linux-3.10-el7.x86_64-x86_64-with-redhat-7.4-Maipo-x86_64-3.5.5-64/lock_dir
INFO (theano.gof.compilelock): Waiting for existing lock by process '4101' (I am process '56041')
INFO (theano.gof.compilelock): To manually release the lock, delete /mainfs/lyceum/grm1g17/.theano/compiledir_Linux-3.10-el7.x86_64-x86_64-with-redhat-7.4-Maipo-x86_64-3.5.5-64/lock_dir
INFO (theano.gof.compilelock): Waiting for existing lock by process '4101' (I am process '56041')
INFO (theano.gof.compilelock): To manually release the lock, delete /mainfs/lyceum/grm1g17/.theano/compiledir_Linux-3.10-el7.x86_64-x86_64-with-redhat-7.4-Maipo-x86_64-3.5.5-64/lock_dir
INFO (theano.gof.compilelock): Waiting for existing lock by process '4101' (I am process '56041')
INFO (theano.gof.compilelock): To manually release the lock, delete /mainfs/lyceum/grm1g17/.theano/compiledir_Linux-3.10-el7.x86_64-x86_64-with-redhat-7.4-Maipo-x86_64-3.5.5-64/lock_dir
INFO (theano.gof.compilelock): Waiting for existing lock by process '4101' (I am process '56041')
INFO (theano.gof.compilelock): To manually release the lock, delete /mainfs/lyceum/grm1g17/.theano/compiledir_Linux-3.10-el7.x86_64-x86_64-with-redhat-7.4-Maipo-x86_64-3.5.5-64/lock_dir
INFO (theano.gof.compilelock): Waiting for existing lock by process '4101' (I am process '56041')
INFO (theano.gof.compilelock): To manually release the lock, delete /mainfs/lyceum/grm1g17/.theano/compiledir_Linux-3.10-el7.x86_64-x86_64-with-redhat-7.4-Maipo-x86_64-3.5.5-64/lock_dir
INFO (theano.gof.compilelock): Waiting for existing lock by process '4101' (I am process '56041')
INFO (theano.gof.compilelock): To manually release the lock, delete /mainfs/lyceum/grm1g17/.theano/compiledir_Linux-3.10-el7.x86_64-x86_64-with-redhat-7.4-Maipo-x86_64-3.5.5-64/lock_dir
Using cuDNN version 7005 on context None
Mapped name None to device cuda: GeForce GTX 1080 Ti (0000:03:00.0)
/lyceum/grm1g17/.conda/envs/localenv/lib/python3.5/importlib/_bootstrap.py:222: RuntimeWarning: numpy.dtype size changed, may indicate binary incompatibility. Expected 96, got 88
  return f(*args, **kwds)
Using Theano backend.
Train path is downloaded ...
Loading train data ...
Loading splits ...
Traceback (most recent call last):
  File "saliency.py", line 312, in <module>
    main_saliencies_jurtz()
  File "saliency.py", line 256, in main_saliencies_jurtz
    compute_tensor_jurtz(X[idx], mask[idx], args.batch, args.label)
IndexError: index 256 is out of bounds for axis 0 with size 256
/lyceum/grm1g17/.conda/envs/localenv/lib/python3.5/importlib/_bootstrap.py:222: RuntimeWarning: numpy.dtype size changed, may indicate binary incompatibility. Expected 96, got 88
  return f(*args, **kwds)
Using cuDNN version 7005 on context None
Mapped name None to device cuda: GeForce GTX 1080 Ti (0000:03:00.0)
/lyceum/grm1g17/.conda/envs/localenv/lib/python3.5/importlib/_bootstrap.py:222: RuntimeWarning: numpy.dtype size changed, may indicate binary incompatibility. Expected 96, got 88
  return f(*args, **kwds)
Using Theano backend.
Train path is downloaded ...
Loading train data ...
Loading splits ...
Traceback (most recent call last):
  File "saliency.py", line 312, in <module>
    main_saliencies_jurtz()
  File "saliency.py", line 256, in main_saliencies_jurtz
    compute_tensor_jurtz(X[idx], mask[idx], args.batch, args.label)
IndexError: index 256 is out of bounds for axis 0 with size 256
/lyceum/grm1g17/.conda/envs/localenv/lib/python3.5/importlib/_bootstrap.py:222: RuntimeWarning: numpy.dtype size changed, may indicate binary incompatibility. Expected 96, got 88
  return f(*args, **kwds)
Using cuDNN version 7005 on context None
Mapped name None to device cuda: GeForce GTX 1080 Ti (0000:03:00.0)
/lyceum/grm1g17/.conda/envs/localenv/lib/python3.5/importlib/_bootstrap.py:222: RuntimeWarning: numpy.dtype size changed, may indicate binary incompatibility. Expected 96, got 88
  return f(*args, **kwds)
Using Theano backend.
Train path is downloaded ...
Loading train data ...
Loading splits ...
Traceback (most recent call last):
  File "saliency.py", line 312, in <module>
    main_saliencies_jurtz()
  File "saliency.py", line 256, in main_saliencies_jurtz
    compute_tensor_jurtz(X[idx], mask[idx], args.batch, args.label)
IndexError: index 256 is out of bounds for axis 0 with size 256
/lyceum/grm1g17/.conda/envs/localenv/lib/python3.5/importlib/_bootstrap.py:222: RuntimeWarning: numpy.dtype size changed, may indicate binary incompatibility. Expected 96, got 88
  return f(*args, **kwds)
Using cuDNN version 7005 on context None
Mapped name None to device cuda: GeForce GTX 1080 Ti (0000:03:00.0)
/lyceum/grm1g17/.conda/envs/localenv/lib/python3.5/importlib/_bootstrap.py:222: RuntimeWarning: numpy.dtype size changed, may indicate binary incompatibility. Expected 96, got 88
  return f(*args, **kwds)
Using Theano backend.
Train path is downloaded ...
Loading train data ...
Loading splits ...
Traceback (most recent call last):
  File "saliency.py", line 312, in <module>
    main_saliencies_jurtz()
  File "saliency.py", line 256, in main_saliencies_jurtz
    compute_tensor_jurtz(X[idx], mask[idx], args.batch, args.label)
IndexError: index 256 is out of bounds for axis 0 with size 256
/lyceum/grm1g17/.conda/envs/localenv/lib/python3.5/importlib/_bootstrap.py:222: RuntimeWarning: numpy.dtype size changed, may indicate binary incompatibility. Expected 96, got 88
  return f(*args, **kwds)
INFO (theano.gof.compilelock): Waiting for existing lock by process '7598' (I am process '1326')
INFO (theano.gof.compilelock): To manually release the lock, delete /mainfs/lyceum/grm1g17/.theano/compiledir_Linux-3.10-el7.x86_64-x86_64-with-redhat-7.4-Maipo-x86_64-3.5.5-64/lock_dir
INFO (theano.gof.compilelock): Waiting for existing lock by process '7598' (I am process '1326')
INFO (theano.gof.compilelock): To manually release the lock, delete /mainfs/lyceum/grm1g17/.theano/compiledir_Linux-3.10-el7.x86_64-x86_64-with-redhat-7.4-Maipo-x86_64-3.5.5-64/lock_dir
Using cuDNN version 7005 on context None
Mapped name None to device cuda: GeForce GTX 1080 Ti (0000:03:00.0)
/lyceum/grm1g17/.conda/envs/localenv/lib/python3.5/importlib/_bootstrap.py:222: RuntimeWarning: numpy.dtype size changed, may indicate binary incompatibility. Expected 96, got 88
  return f(*args, **kwds)
Using Theano backend.
Train path is downloaded ...
Loading train data ...
Loading splits ...
Traceback (most recent call last):
  File "saliency.py", line 312, in <module>
    main_saliencies_jurtz()
  File "saliency.py", line 256, in main_saliencies_jurtz
    compute_tensor_jurtz(X[idx], mask[idx], args.batch, args.label)
IndexError: index 256 is out of bounds for axis 0 with size 256
