Running SLURM prolog script on pink54
===============================================================================
Job started on Tue Aug  7 12:45:52 BST 2018
Job ID          : 125065
Job name        : saliency-batch
WorkDir         : /mainfs/lyceum/grm1g17/lasagne4bio/test_saliency
Partition       : lyceum
Num hosts       : 1
Num cores       : 14
Num of tasks    : 14
Hosts allocated : pink54
Job Output Follows ...
===============================================================================
/lyceum/grm1g17/.conda/envs/localenv/lib/python3.5/importlib/_bootstrap.py:222: RuntimeWarning: numpy.dtype size changed, may indicate binary incompatibility. Expected 96, got 88
  return f(*args, **kwds)
Using cuDNN version 7005 on context None
Mapped name None to device cuda: GeForce GTX 1080 Ti (0000:83:00.0)
/lyceum/grm1g17/.conda/envs/localenv/lib/python3.5/importlib/_bootstrap.py:222: RuntimeWarning: numpy.dtype size changed, may indicate binary incompatibility. Expected 96, got 88
  return f(*args, **kwds)
Using Theano backend.
Loading test data ...
Traceback (most recent call last):
  File "saliency.py", line 173, in <module>
    main_saliencies_jurtz()
  File "saliency.py", line 165, in main_saliencies_jurtz
    X_batch, mask_batch = dater.get_batch_from_seq(first_seq)
  File "/mainfs/lyceum/grm1g17/lasagne4bio/test_saliency/utils.py", line 70, in get_batch_from_seq
    return self.X[idx], self.mask[idx]
IndexError: index 5568 is out of bounds for axis 0 with size 640
/lyceum/grm1g17/.conda/envs/localenv/lib/python3.5/importlib/_bootstrap.py:222: RuntimeWarning: numpy.dtype size changed, may indicate binary incompatibility. Expected 96, got 88
  return f(*args, **kwds)
Using cuDNN version 7005 on context None
Mapped name None to device cuda: GeForce GTX 1080 Ti (0000:83:00.0)
/lyceum/grm1g17/.conda/envs/localenv/lib/python3.5/importlib/_bootstrap.py:222: RuntimeWarning: numpy.dtype size changed, may indicate binary incompatibility. Expected 96, got 88
  return f(*args, **kwds)
Using Theano backend.
Loading test data ...
Traceback (most recent call last):
  File "saliency.py", line 173, in <module>
    main_saliencies_jurtz()
  File "saliency.py", line 165, in main_saliencies_jurtz
    X_batch, mask_batch = dater.get_batch_from_seq(first_seq)
  File "/mainfs/lyceum/grm1g17/lasagne4bio/test_saliency/utils.py", line 70, in get_batch_from_seq
    return self.X[idx], self.mask[idx]
IndexError: index 5568 is out of bounds for axis 0 with size 640
/lyceum/grm1g17/.conda/envs/localenv/lib/python3.5/importlib/_bootstrap.py:222: RuntimeWarning: numpy.dtype size changed, may indicate binary incompatibility. Expected 96, got 88
  return f(*args, **kwds)
INFO (theano.gof.compilelock): Waiting for existing lock by process '33283' (I am process '45423')
INFO (theano.gof.compilelock): To manually release the lock, delete /mainfs/lyceum/grm1g17/.theano/compiledir_Linux-3.10-el7.x86_64-x86_64-with-redhat-7.4-Maipo-x86_64-3.5.5-64/lock_dir
INFO (theano.gof.compilelock): Waiting for existing lock by process '33283' (I am process '45423')
INFO (theano.gof.compilelock): To manually release the lock, delete /mainfs/lyceum/grm1g17/.theano/compiledir_Linux-3.10-el7.x86_64-x86_64-with-redhat-7.4-Maipo-x86_64-3.5.5-64/lock_dir
INFO (theano.gof.compilelock): Waiting for existing lock by process '33283' (I am process '45423')
INFO (theano.gof.compilelock): To manually release the lock, delete /mainfs/lyceum/grm1g17/.theano/compiledir_Linux-3.10-el7.x86_64-x86_64-with-redhat-7.4-Maipo-x86_64-3.5.5-64/lock_dir
INFO (theano.gof.compilelock): Waiting for existing lock by process '33283' (I am process '45423')
INFO (theano.gof.compilelock): To manually release the lock, delete /mainfs/lyceum/grm1g17/.theano/compiledir_Linux-3.10-el7.x86_64-x86_64-with-redhat-7.4-Maipo-x86_64-3.5.5-64/lock_dir
INFO (theano.gof.compilelock): Waiting for existing lock by process '33283' (I am process '45423')
INFO (theano.gof.compilelock): To manually release the lock, delete /mainfs/lyceum/grm1g17/.theano/compiledir_Linux-3.10-el7.x86_64-x86_64-with-redhat-7.4-Maipo-x86_64-3.5.5-64/lock_dir
INFO (theano.gof.compilelock): Waiting for existing lock by process '33283' (I am process '45423')
INFO (theano.gof.compilelock): To manually release the lock, delete /mainfs/lyceum/grm1g17/.theano/compiledir_Linux-3.10-el7.x86_64-x86_64-with-redhat-7.4-Maipo-x86_64-3.5.5-64/lock_dir
INFO (theano.gof.compilelock): Waiting for existing lock by process '33283' (I am process '45423')
INFO (theano.gof.compilelock): To manually release the lock, delete /mainfs/lyceum/grm1g17/.theano/compiledir_Linux-3.10-el7.x86_64-x86_64-with-redhat-7.4-Maipo-x86_64-3.5.5-64/lock_dir
INFO (theano.gof.compilelock): Waiting for existing lock by process '33283' (I am process '45423')
INFO (theano.gof.compilelock): To manually release the lock, delete /mainfs/lyceum/grm1g17/.theano/compiledir_Linux-3.10-el7.x86_64-x86_64-with-redhat-7.4-Maipo-x86_64-3.5.5-64/lock_dir
INFO (theano.gof.compilelock): Waiting for existing lock by process '33283' (I am process '45423')
INFO (theano.gof.compilelock): To manually release the lock, delete /mainfs/lyceum/grm1g17/.theano/compiledir_Linux-3.10-el7.x86_64-x86_64-with-redhat-7.4-Maipo-x86_64-3.5.5-64/lock_dir
INFO (theano.gof.compilelock): Waiting for existing lock by process '33283' (I am process '45423')
INFO (theano.gof.compilelock): To manually release the lock, delete /mainfs/lyceum/grm1g17/.theano/compiledir_Linux-3.10-el7.x86_64-x86_64-with-redhat-7.4-Maipo-x86_64-3.5.5-64/lock_dir
INFO (theano.gof.compilelock): Waiting for existing lock by process '33283' (I am process '45423')
INFO (theano.gof.compilelock): To manually release the lock, delete /mainfs/lyceum/grm1g17/.theano/compiledir_Linux-3.10-el7.x86_64-x86_64-with-redhat-7.4-Maipo-x86_64-3.5.5-64/lock_dir
INFO (theano.gof.compilelock): Waiting for existing lock by process '33283' (I am process '45423')
INFO (theano.gof.compilelock): To manually release the lock, delete /mainfs/lyceum/grm1g17/.theano/compiledir_Linux-3.10-el7.x86_64-x86_64-with-redhat-7.4-Maipo-x86_64-3.5.5-64/lock_dir
INFO (theano.gof.compilelock): Waiting for existing lock by process '33283' (I am process '45423')
INFO (theano.gof.compilelock): To manually release the lock, delete /mainfs/lyceum/grm1g17/.theano/compiledir_Linux-3.10-el7.x86_64-x86_64-with-redhat-7.4-Maipo-x86_64-3.5.5-64/lock_dir
INFO (theano.gof.compilelock): Waiting for existing lock by process '33283' (I am process '45423')
INFO (theano.gof.compilelock): To manually release the lock, delete /mainfs/lyceum/grm1g17/.theano/compiledir_Linux-3.10-el7.x86_64-x86_64-with-redhat-7.4-Maipo-x86_64-3.5.5-64/lock_dir
INFO (theano.gof.compilelock): Waiting for existing lock by process '33963' (I am process '45423')
INFO (theano.gof.compilelock): To manually release the lock, delete /mainfs/lyceum/grm1g17/.theano/compiledir_Linux-3.10-el7.x86_64-x86_64-with-redhat-7.4-Maipo-x86_64-3.5.5-64/lock_dir
Using cuDNN version 7005 on context None
Mapped name None to device cuda: GeForce GTX 1080 Ti (0000:83:00.0)
/lyceum/grm1g17/.conda/envs/localenv/lib/python3.5/importlib/_bootstrap.py:222: RuntimeWarning: numpy.dtype size changed, may indicate binary incompatibility. Expected 96, got 88
  return f(*args, **kwds)
Using Theano backend.
Loading test data ...
Traceback (most recent call last):
  File "saliency.py", line 173, in <module>
    main_saliencies_jurtz()
  File "saliency.py", line 165, in main_saliencies_jurtz
    X_batch, mask_batch = dater.get_batch_from_seq(first_seq)
  File "/mainfs/lyceum/grm1g17/lasagne4bio/test_saliency/utils.py", line 70, in get_batch_from_seq
    return self.X[idx], self.mask[idx]
IndexError: index 5568 is out of bounds for axis 0 with size 640
/lyceum/grm1g17/.conda/envs/localenv/lib/python3.5/importlib/_bootstrap.py:222: RuntimeWarning: numpy.dtype size changed, may indicate binary incompatibility. Expected 96, got 88
  return f(*args, **kwds)
Using cuDNN version 7005 on context None
Mapped name None to device cuda: GeForce GTX 1080 Ti (0000:83:00.0)
/lyceum/grm1g17/.conda/envs/localenv/lib/python3.5/importlib/_bootstrap.py:222: RuntimeWarning: numpy.dtype size changed, may indicate binary incompatibility. Expected 96, got 88
  return f(*args, **kwds)
Using Theano backend.
Loading test data ...
Traceback (most recent call last):
  File "saliency.py", line 173, in <module>
    main_saliencies_jurtz()
  File "saliency.py", line 165, in main_saliencies_jurtz
    X_batch, mask_batch = dater.get_batch_from_seq(first_seq)
  File "/mainfs/lyceum/grm1g17/lasagne4bio/test_saliency/utils.py", line 70, in get_batch_from_seq
    return self.X[idx], self.mask[idx]
IndexError: index 5568 is out of bounds for axis 0 with size 640
/lyceum/grm1g17/.conda/envs/localenv/lib/python3.5/importlib/_bootstrap.py:222: RuntimeWarning: numpy.dtype size changed, may indicate binary incompatibility. Expected 96, got 88
  return f(*args, **kwds)
Using cuDNN version 7005 on context None
Mapped name None to device cuda: GeForce GTX 1080 Ti (0000:83:00.0)
/lyceum/grm1g17/.conda/envs/localenv/lib/python3.5/importlib/_bootstrap.py:222: RuntimeWarning: numpy.dtype size changed, may indicate binary incompatibility. Expected 96, got 88
  return f(*args, **kwds)
Using Theano backend.
Loading test data ...
Traceback (most recent call last):
  File "saliency.py", line 173, in <module>
    main_saliencies_jurtz()
  File "saliency.py", line 165, in main_saliencies_jurtz
    X_batch, mask_batch = dater.get_batch_from_seq(first_seq)
  File "/mainfs/lyceum/grm1g17/lasagne4bio/test_saliency/utils.py", line 70, in get_batch_from_seq
    return self.X[idx], self.mask[idx]
IndexError: index 5568 is out of bounds for axis 0 with size 640
/lyceum/grm1g17/.conda/envs/localenv/lib/python3.5/importlib/_bootstrap.py:222: RuntimeWarning: numpy.dtype size changed, may indicate binary incompatibility. Expected 96, got 88
  return f(*args, **kwds)
Using cuDNN version 7005 on context None
Mapped name None to device cuda: GeForce GTX 1080 Ti (0000:83:00.0)
/lyceum/grm1g17/.conda/envs/localenv/lib/python3.5/importlib/_bootstrap.py:222: RuntimeWarning: numpy.dtype size changed, may indicate binary incompatibility. Expected 96, got 88
  return f(*args, **kwds)
Using Theano backend.
Loading test data ...
Traceback (most recent call last):
  File "saliency.py", line 173, in <module>
    main_saliencies_jurtz()
  File "saliency.py", line 165, in main_saliencies_jurtz
    X_batch, mask_batch = dater.get_batch_from_seq(first_seq)
  File "/mainfs/lyceum/grm1g17/lasagne4bio/test_saliency/utils.py", line 70, in get_batch_from_seq
    return self.X[idx], self.mask[idx]
IndexError: index 5568 is out of bounds for axis 0 with size 640
/lyceum/grm1g17/.conda/envs/localenv/lib/python3.5/importlib/_bootstrap.py:222: RuntimeWarning: numpy.dtype size changed, may indicate binary incompatibility. Expected 96, got 88
  return f(*args, **kwds)
Using cuDNN version 7005 on context None
Mapped name None to device cuda: GeForce GTX 1080 Ti (0000:83:00.0)
/lyceum/grm1g17/.conda/envs/localenv/lib/python3.5/importlib/_bootstrap.py:222: RuntimeWarning: numpy.dtype size changed, may indicate binary incompatibility. Expected 96, got 88
  return f(*args, **kwds)
Using Theano backend.
Loading test data ...
Traceback (most recent call last):
  File "saliency.py", line 173, in <module>
    main_saliencies_jurtz()
  File "saliency.py", line 165, in main_saliencies_jurtz
    X_batch, mask_batch = dater.get_batch_from_seq(first_seq)
  File "/mainfs/lyceum/grm1g17/lasagne4bio/test_saliency/utils.py", line 70, in get_batch_from_seq
    return self.X[idx], self.mask[idx]
IndexError: index 5568 is out of bounds for axis 0 with size 640
/lyceum/grm1g17/.conda/envs/localenv/lib/python3.5/importlib/_bootstrap.py:222: RuntimeWarning: numpy.dtype size changed, may indicate binary incompatibility. Expected 96, got 88
  return f(*args, **kwds)
Using cuDNN version 7005 on context None
Mapped name None to device cuda: GeForce GTX 1080 Ti (0000:83:00.0)
/lyceum/grm1g17/.conda/envs/localenv/lib/python3.5/importlib/_bootstrap.py:222: RuntimeWarning: numpy.dtype size changed, may indicate binary incompatibility. Expected 96, got 88
  return f(*args, **kwds)
Using Theano backend.
Loading test data ...
Traceback (most recent call last):
  File "saliency.py", line 173, in <module>
    main_saliencies_jurtz()
  File "saliency.py", line 165, in main_saliencies_jurtz
    X_batch, mask_batch = dater.get_batch_from_seq(first_seq)
  File "/mainfs/lyceum/grm1g17/lasagne4bio/test_saliency/utils.py", line 70, in get_batch_from_seq
    return self.X[idx], self.mask[idx]
IndexError: index 5568 is out of bounds for axis 0 with size 640
==============================================================================
Running epilogue script on pink54.

Submit time  : 2018-08-07T11:14:52
Start time   : 2018-08-07T12:45:52
End time     : 2018-08-07T13:00:49
Elapsed time : 00:14:57 (Timelimit=04:40:00)

Job ID: 125065
Array Job ID: 125045_87
Cluster: i5
User/Group: grm1g17/fp
State: FAILED (exit code 1)
Nodes: 1
Cores per node: 14
CPU Utilized: 00:02:50
**** Please note that the CPU efficency of your job is less than 50% ****
**** Ask the HPC team for advice -- if you need it
**** CPU Efficiency: 1.35% of 03:29:18 core-walltime

Memory Utilized: 1.55 GB

